Workbook

Sheet Biomarker_Disease
A1: BiomarkerID | B1: Biomarker_Name | C1: Diseasename | D1: ICD11 | E1: ICD10 | F1: ICD9
A2: BM003549 | B2: Neutrophil gelatinase-associated lipocalin (LCN2) | C2: Smallpox | D2: ICD-11: 1E70 | E2: ICD-10: B03 | F2: .
A3: BM002188 | B3: Monocyte chemoattractantprotein-1 (MCP-1) | C3: Amyotrophic lateral sclerosis | D3: ICD-11: 8B60.0 | E3: . | F3: ICD-9: 335.2
A4: BM001695 | B4: HLA class I histocompatibility antigen, B-8 alpha chain (HLA-B) | C4: Myasthenia gravis | D4: ICD-11: 8C6Y | E4: ICD-10: G70.0 | F4: ICD-9: 358
A5: BM000711 | B5: Muscle-specific kinase (MuSK) antibody | C5: Myasthenia gravis | D5: ICD-11: 8C6Y | E5: ICD-10: G70.0 | F5: ICD-9: 358
A6: BM002220 | B6: Muscle-specific kinase (MuSK) antibody | C6: Myasthenia gravis | D6: ICD-11: 8C6Y | E6: ICD-10: G70.0 | F6: ICD-9: 358
A7: BM002933 | B7: Vascular cell adhesion molecule (sVCAM) | C7: Cardiovascular disease | D7: ICD-11: BA00-BE2Z | E7: ICD-10: I00-I99 | F7: .
A8: BM002691 | B8: Sodium/myo-inositol cotransporter (SLC5A3) | C8: Coronary artery disease | D8: ICD-11: BA80 | E8: ICD-10: I25.1, I25.4 | F8: .
A9: BM002750 | B9: Transforming growth factor b (TGF-b) | C9: Asthma | D9: ICD-11: CA23 | E9: ICD-10: J45, J45.8 | F9: ICD-9: 493
A10: BM001941 | B10: Keratin, type II cytoskeletal 1 (KRT1) | C10: Psoriasis vulgaris | D10: ICD-11: EA90 | E10: . | F10: ICD-9: 696
A11: BM001696 | B11: HLA class I histocompatibility antigen, Cw-6 alpha chain (HLA-C) | C11: Psoriasis vulgaris | D11: ICD-11: EA90 | E11: . | F11: ICD-9: 696
A12: BM000396 | B12: HLA class II histocompatibility antigen, DRB1-12 beta chain (HLA-DRB1) | C12: Rheumatoid arthritis | D12: ICD-11: FA20 | E12: . | F12: .
... A2513: BM003018 | B2513: Zinc finger protein ZPR1 (ZPR1) | C2513: Coronary artery disease | D2513: ICD-11: BA80 | E2513: ICD-10: I25.1, I25.4 | F2513: .

Sheet Biomarker_Disease (2)
A1: BiomarkerID | B1: Biomarker_Name | C1: Diseasename | D1: ICD11 | E1: ICD10 | F1: ICD9
A2: BM003549 | B2: Neutrophil gelatinase-associated lipocalin (LCN2) | C2: Smallpox | D2: ICD-11: 1E70 | E2: ICD-10: B03 | F2: .
A3: BM002188 | B3: Monocyte chemoattractantprotein-1 (MCP-1) | C3: Amyotrophic lateral sclerosis | D3: ICD-11: 8B60.0 | E3: . | F3: ICD-9: 335.2
A4: BM001695 | B4: HLA class I histocompatibility antigen, B-8 alpha chain (HLA-B) | C4: Myasthenia gravis | D4: ICD-11: 8C6Y | E4: ICD-10: G70.0 | F4: ICD-9: 358
A5: BM000711 | B5: Muscle-specific kinase (MuSK) antibody | C5: Myasthenia gravis | D5: ICD-11: 8C6Y | E5: ICD-10: G70.0 | F5: ICD-9: 358
A6: BM002220 | B6: Muscle-specific kinase (MuSK) antibody | C6: Myasthenia gravis | D6: ICD-11: 8C6Y | E6: ICD-10: G70.0 | F6: ICD-9: 358
A7: BM002933 | B7: Vascular cell adhesion molecule (sVCAM) | C7: Cardiovascular disease | D7: ICD-11: BA00-BE2Z | E7: ICD-10: I00-I99 | F7: .
A8: BM002691 | B8: Sodium/myo-inositol cotransporter (SLC5A3) | C8: Coronary artery disease | D8: ICD-11: BA80 | E8: ICD-10: I25.1, I25.4 | F8: .
A9: BM002750 | B9: Transforming growth factor b (TGF-b) | C9: Asthma | D9: ICD-11: CA23 | E9: ICD-10: J45, J45.8 | F9: ICD-9: 493
A10: BM001941 | B10: Keratin, type II cytoskeletal 1 (KRT1) | C10: Psoriasis vulgaris | D10: ICD-11: EA90 | E10: . | F10: ICD-9: 696
A11: BM001696 | B11: HLA class I histocompatibility antigen, Cw-6 alpha chain (HLA-C) | C11: Psoriasis vulgaris | D11: ICD-11: EA90 | E11: . | F11: ICD-9: 696
A12: BM000396 | B12: HLA class II histocompatibility antigen, DRB1-12 beta chain (HLA-DRB1) | C12: Rheumatoid arthritis | D12: ICD-11: FA20 | E12: . | F12: .
... A2513: BM003018 | B2513: Zinc finger protein ZPR1 (ZPR1) | C2513: Coronary artery disease | D2513: ICD-11: BA80 | E2513: ICD-10: I25.1, I25.4 | F2513: .

Sheet Sheet2
A1: BiomarkerID | B1: Biomarker_Name | C1: Diseasename | D1: ICD11 | E1: ICD10 | F1: ICD9
A2: BM002860 | B2: Globoside alpha-1,3-N-acetylgalactosaminyltransferase 1 (GBGT1) | C2: Inflammation | D2: ICD-11: 1A00-CA43.1 | E2: . | F2: .
A3: BM002862 | B3: Globoside alpha-1,3-N-acetylgalactosaminyltransferase 1 (GBGT1) | C3: Inflammation | D3: ICD-11: 1A00-CA43.1 | E3: . | F3: .
A4: BM002868 | B4: Globoside alpha-1,3-N-acetylgalactosaminyltransferase 1 (GBGT1) | C4: Inflammation | D4: ICD-11: 1A00-CA43.1 | E4: . | F4: .
A5: BM002870 | B5: Globoside alpha-1,3-N-acetylgalactosaminyltransferase 1 (GBGT1) | C5: Inflammation | D5: ICD-11: 1A00-CA43.1 | E5: . | F5: .
A6: BM001759 | B6: Interleukin-1 family member 10 (IL1F10) | C6: Inflammation | D6: ICD-11: 1A00-CA43.1 | E6: . | F6: .
A7: BM002681 | B7: Lymphocyte adaptor protein LNK | C7: Inflammation | D7: ICD-11: 1A00-CA43.1 | E7: . | F7: .
A8: BM002346 | B8: Nuclear factor of k light polypeptide gene enhancer in B-cells inhibitor | C8: Inflammation | D8: ICD-11: 1A00-CA43.1 | E8: . | F8: .
A9: BM002551 | B9: Poly(A) binding protein | C9: Inflammation | D9: ICD-11: 1A00-CA43.1 | E9: . | F9: .
A10: BM002713 | B10: P-selectin | C10: Inflammation | D10: ICD-11: 1A00-CA43.1 | E10: . | F10: .
A11: BM000031 | B11: Alpha-fetoprotein | C11: Hepatocellular carcinoma | D11: ICD-11: 2C12.02 | E11: ICD-10: C22.0 | F11: ICD-9: 155
A12: BM000698 | B12: a-2 macroglobulin, haptoglobin, total bilirubin, g-glutamyl transferase, ALT, AS T, total cholesterol, TG, fasting blood glucose. | C12: Non-alcoholic steatohepatitis | D12: ICD-11: DB92.1 | E12: ICD-10: K75.8 | F12: ICD-9: 571.8
... A55: BM002808 | B55: Tumor necrosis factor (TNF) | C55: Non-alcoholic steatohepatitis | D55: ICD-11: DB92.1 | E55: ICD-10: K75.8 | F55: ICD-9: 571.8

Sheet Class
A1: Type | B1: Biomarker_ID | C1: Normal Range | D1: Clinical Significance | E1: Description
A2: Predictive Biomarkers | B2: Liver Injury Markers | E2: Liver injury markers are biochemical, molecular, and histopathological indicators used to assess hepatocellular damage, cholestasis, liver function, inflammation, fibrosis, and regeneration.
B5: Alanine Aminotransferase (ALT) | C5: 7–56 U/L | D5: Most specific marker for liver injury | E5: ALT is an enzyme found in the liver that helps convert proteins into energy for the liver cells. When the liver is damaged, ALT is released into the bloodstream and levels increase. This test is sometimes referred to as SGPT.
B6: Aspartate Aminotransferase (AST) | C6: 10–40 U/L | D6: Liver, heart, muscle injury | E6: AST is an enzyme that helps the body break down amino acids. Like ALT, AST is usually present in blood at low levels. An increase in AST levels may mean liver damage, liver disease or muscle damage. This test is sometimes referred to as SGOT.
B7: Gamma-Glutamyl Transferase (GGT) | C7: 5 to 48 U/L | D7: Liver and biliary tract disease | E7: GGT is an enzyme in the blood. Higher-than-usual levels may mean liver or bile duct damage. This test is nonspecific and may be elevated in conditions other than liver disease.
B8: Alkaline phosphatase (ALP) | C8: Adult Men: 40 to 129 U/L Adult Women: 35 to 104 U/L (with temporary elevations expected during pregnancy) Children and Adolescents: 130 to 500+ U/L, | D8: Liver diseases (specifically bile duct obstruction) and bone disorders | E8: ALP is an enzyme found in the liver and bone and is important for breaking down proteins. Higher-than-usual levels of ALP may mean liver damage or disease, such as a blocked bile duct, or certain bone diseases, as this enzyme is also present in bones.
B9: Bilirubin | C9: Total Bilirubin: 0.1 – 1.2 mg/dL Direct (Conjugated): 0.0 – 0.3 mg/dL Indirect (Unconjugated): 0.2 – 0.8 mg/dL | D9: Liver diseases (like hepatitis or cirrhosis), evaluate blocked bile ducts, and investigate hemolytic anemia | E9: Bilirubin is a substance produced during the breakdown of red blood cells. Bilirubin passes through the liver and is excreted in stool. Higher levels of bilirubin might mean liver damage or disease. At times, conditions such as a blockage of the liver ducts or certain types of anemia also can lead to elevated bilirubin.
B10: Lipid Metabolism Markers | E10: Lipid metabolism markers are blood-based biomarkers used to assess how your body processes fats. They identify risks for cardiovascular disease and metabolic syndrome. Key tests include LDL cholesterol (bad cholesterol), HDL cholesterol (good cholesterol), Triglycerides (stored fat), Total Cholesterol, and advanced markers like Apolipoproteins (ApoB/ApoA-1) and Lp(a). These tests measure the balance of lipids in the blood to help detect dyslipidemia. When these markers are abnormal, it indicates a high risk of plaque building up in your arteries (atherosclerosis).
B13: Total cholesterol | C13: Desirable/Normal: Less than 200 mg/dL Borderline high: 200 to 239 mg/dL High: 240 mg/dL or higher | D13: Cardiovascular risk assessment; high levels drive plaque buildup, increasing the risk of coronary artery disease, heart attacks, and strokes | E13: Total cholesterol measures the complete amount of cholesterol—both "bad" (LDL) and "good" (HDL)—circulating in your blood. Its clinical significance lies in cardiovascular risk assessment; high levels drive plaque buildup, increasing the risk of coronary artery disease, heart attacks, and strokes
B14: LDL-C | C14: Optimal: Less than 100 mg/dLNear/Above Optimal: 100–129 mg/dL Borderline High: 130–159 mg/dL High: 160–189 mg/dL Very High: 190 mg/dL and above | D14: Massive hepatic necrosis | E14: LDL-C stands for low-density lipoprotein cholesterol. Known as "bad" cholesterol, it carries cholesterol to body tissues. Excess LDL-C builds up on artery walls as plaque, raising the risk of heart disease and strokes. Experts recommend keeping levels below 100 milligrams per deciliter (mg/dL).Because cholesterol cannot dissolve in the blood, it must be carried by proteins called lipoproteins. LDL-C represents the specific amount of cholesterol circulating inside these low-density particles. While the body requires some cholesterol to build cells and make hormones, high concentrations of LDL-C can lead to atherosclerosis, a condition where the arteries narrow and harden. If plaque ruptures, it can cause dangerous blood clots, potentially triggering a heart attack or stroke
B15: HDL-C | C15: Low HDL (Increased Risk): < 40 mg/dL (males) or < 50 mg/dL (females) Normal HDL: 40 to 80 mg/dL (males) or 50 to 80 mg/dL (females) High HDL (Optimal Protection): ≥ 60 mg/dL for both men and women | D15: A marker for cardiovascular risk. While low levels indicate a higher risk for atherosclerosis and heart disease, extremely high levels are no longer universally considered protective and can paradoxically indicate inflammation or disease. | E15: HDL-C (High-Density Lipoprotein Cholesterol) is the cholesterol transported by high-density lipoproteins. Often called "good" cholesterol, it acts like a scavenger in the bloodstream, absorbing excess cholesterol and plaque-forming fats and carrying them back to the liver to be safely flushed from the body. Because this process actively clears the arteries, higher levels of HDL-C are linked to a lower risk of heart disease and stroke.
B16: Triglycerides | C16: Normal: Less than 150Less than 1.7 Borderline: High150 to 1991.7 to 2.2 High: 200 to 4992.3 to 5.6 Very High: 500 or higher | D16: Ability to reflect metabolic health and cardiovascular risk; elevated levels (hypertriglyceridemia) are directly linked to the hardening of arteries, metabolic syndrome, and acute pancreatitis | E16: Triglycerides are the most common type of fat in our body. They store excess calories from your diet for energy and are transported through your bloodstream. A normal fasting level is typically less than 150 mg/dL, while levels above 200 mg/dL are considered high. Chemically, a triglyceride is an ester derived from a molecule of glycerol combined with three fatty acid chains (represented generally as RCOOH). They make up most of the fats you eat and are also produced by your liver from excess carbohydrates and calories. After you eat, your body converts any calories it doesn't need to use right away into triglycerides, which are then stored in your fat cells. Between meals, hormones release these triglycerides to provide your body with energy.
B17: Free fatty acids | C17: Adults (≥18 years): 0.00–0.72 mmol/L Females: Typically 0.1–0.45 mmol/L Males: Typically 0.1–0.60 mmol/L | D17: Primary indicator of metabolic stress. High concentrations are directly linked to insulin resistance, Type 2 diabetes, obesity, and cardiovascular disease | E17: Free fatty acids (FFAs) are unattached organic compounds found in lipids and fats. Structurally, they consist of a hydrocarbon chain ending in a carboxylic acid group (-COOH). They serve as vital energy substrates, metabolic regulators, and building blocks for cellular membranes, and circulate in the bloodstream bound to albumin.
B18: Glucose/Insulin Resistance Markers | C18: Normal: Below 100 mg/dL (5.6 mmol/L) Prediabetes: 100 to 125 mg/dL (5.6 to 6.9 mmol/L) Diabetes: 126 mg/dL (7.0 mmol/L) or higher (confirmed by two separate tests) | E18: Insulin resistance (IR) markers help determine how effectively your body uses insulin. Key indicators include a HOMA-IR score (calculated from fasting glucose and fasting insulin), HbA1c, and lipid markers like Triglycerides and HDL. For optimal metabolic health, these levels should fall within specific ranges.
B19: Fasting glucose | C19: Adult: between 70 and 99 mg/dL (3.9 to 5.5 mmol/L) | D19: Primarily used to screen for or diagnose diabetes and prediabetes | E19: Fasting blood sugar measures the amount of glucose (sugar) in your bloodstream after you have not eaten or consumed anything besides water for at least 8 hours. It evaluates your body's baseline ability to regulate blood sugar overnight and is primarily used to screen for prediabetes and diabetes. To ensure accurate results, you should avoid eating and drinking (except water) for 8 to 12 hours before the test. This is typically done overnight, with the blood sample drawn first thing in the morning. Always consult your doctor before the test if you are taking any prescription medications, as some may interfere with your blood sugar levels.
B20: HbA1c | C20: Normal: Below 5.7% Prediabetes: 5.7% to 6.4% Diabetes: 6.5% or higher (on two separate tests) | D20: Primarily used to diagnose type 2 diabetes and prediabetes, and to monitor long-term glycemic control | E20: HbA1c (Hemoglobin A1c) measures your average blood sugar levels over the past two to three months. It checks how much sugar is attached to the oxygen-carrying protein in your red blood cells. It is primarily used to diagnose prediabetes and diabetes, and to monitor long-term blood sugar management.
B21: Insulin | C21: Fasting Insulin: Optimal / Low Risk: < 10 µIU/mL Borderline / Early Resistance: 10 – 15 µIU/mL Elevated / Insulin Resistance: > 15 – 25 µIU/mL Postprandial: 30 minutes after eating: 30 – 230 µIU/mL 1 hour after eating: 18 – 276 µIU/mL 2 hours after eating: < 16 to 166 µIU/mL 3+ hours after eating: Returns to normal fasting baseline | D21: Diagnosing and managing metabolic conditions such as diabetes mellitus, insulin resistance, and hypoglycemia | E21: Insulin is a vital peptide hormone produced by the pancreas that regulates blood sugar by allowing cells to absorb glucose from the bloodstream for energy. When this system fails, it leads to conditions like diabetes. Sugar Regulation: When you eat, carbohydrates break down into glucose, entering the bloodstream and raising blood sugar. This triggers the pancreas to release insulin. Energy Delivery: Insulin acts like a "key" that unlocks cell walls in muscles, fat, and the liver, allowing glucose to enter and fuel the body. Storage: Extra glucose is converted into glycogen and stored in the liver and muscles for later use.
B22: HOMA-IR | C22: Optimal insulin sensitivity: Below 1.0 Normal / healthy range: 1.0 to 2.5 Suggests significant insulin resistance: Above 2.5 | D22: A vital blood test used to calculate how effectively your body uses insulin | E22: HOMA-IR (Homeostatic Model Assessment of Insulin Resistance) measures how efficiently your body uses insulin. Calculated using fasting blood glucose and insulin levels, the test evaluates your metabolic health and helps assess your risk for developing prediabetes, type 2 diabetes, and cardiovascular conditions. Early Detection: It identifies insulin resistance years before blood sugar levels rise enough to trigger a type 2 diabetes diagnosis. Evaluating Metabolic Risks: High scores indicate an increased risk for metabolic syndrome, prediabetes, cardiovascular disease, fatty liver, and polycystic ovary syndrome (PCOS). Monitoring Treatment: It allows doctors and patients to track how well lifestyle changes (like diet and weight loss) or medications are improving the body's insulin sensitivity
B23: Adiponectin | C23: Men: 4 to 26 μg/mL Women: 5 to 37 μg/mL | D23: A biomarker for metabolic and cardiovascular disorders | E23: Adiponectin is an abundant protein hormone and adipokine secreted primarily by adipose tissue. It governs energy homeostasis by increasing insulin sensitivity, reducing hepatic glucose production, and promoting fatty acid oxidation. It also exerts potent anti-inflammatory effects. Metabolic Regulation: It enhances cells' responsiveness to insulin, lowering blood sugar and protecting against type 2 diabetes. Cardiovascular Protection: It has anti-atherogenic properties, reducing vascular inflammation and preventing plaque buildup in arteries. Inverse Correlation with Obesity: Serum adiponectin levels are surprisingly lower in obese individuals and those with metabolic syndrome, despite it being a fat-derived hormone. Structural Forms: It is a 244-amino-acid polypeptide that circulates in multimeric species, with high-molecular-weight (HMW) forms being the most biologically active.
B24: Inflammatory Markers | E24: Inflammation markers are blood tests that measure proteins or cell changes indicating inflammation in your body. The most common markers are C-reactive protein (CRP) and Erythrocyte Sedimentation Rate (ESR), which point to an active inflammatory process without identifying its specific root cause.Healthcare providers rely on these markers to detect infections, manage autoimmune diseases (like arthritis), and track the severity of chronic conditions
B25: TNF-α | C25: 0 to 8.1 pg/mL | D25: A primary driver of autoimmune diseases and as a complex biomarker in cancer progression, infection response, and paraneoplastic cachexia | E25: TNF-α (Tumor Necrosis Factor alpha) is a primary immune system cytokine that regulates inflammation and immune cell communication. Released primarily by active macrophages during infection or injury, it triggers localized swelling, fever, and cell death to help the body fight off pathogens and tumors.
B26: IL-6 | C26: 0 and 5 pg/mL | D26: A primary driver of the acute-phase response, making it a critical biomarker for infections, autoimmune disorders, and chronic inflammation | E26: IL-6 (Interleukin-6) is a type of small signaling protein called a cytokine. It plays a critical role in your body's immune system, acting as a conductor for inflammation and the body's defense response to infections, trauma, and tissue injuries. Immune Response: Secreted by white blood cells (like macrophages and T-cells), IL-6 alerts the immune system to pathogens and helps B-cells mature into antibody-producing cells. Triggering Fever: IL-6 acts as a pyrogen. It signals the brain to raise your body temperature when fighting off an infection. Acute Phase: It travels to the liver to stimulate the production of acute-phase proteins (like C-reactive protein or CRP), which are common markers of inflammation
B27: IL-1β | C27: <3.9 pg/mL and 11.7 pg/mL | D27: A gatekeeper of inflammation; excessive or chronic signaling drives multiple autoinflammatory, autoimmune, and cardiovascular diseases | E27: IL-1β (Interleukin-1 beta) is a potent pro-inflammatory cytokine and "endogenous pyrogen" produced by activated immune cells like macrophages. It mediates the body's innate and adaptive immune responses, drives the inflammatory pain pathway, and is responsible for inducing fever by altering the brain's temperature-control centers. Unlike most proteins, IL-1β requires a tight, two-step security system before it can become active: Priming: Inflammatory signals prompt immune cells to synthesize the inactive precursor, pro-IL-1β. Activation: Danger signals activate a specialized protein complex known as the inflammasome. This triggers the enzyme caspase-1, which cleaves the inactive precursor into the mature, biologically active IL-1β cytokine
B28: MCP-1 | C28: Between 150 and 350 pg/mL | D28: A key mediator of inflammation, driving the migration and infiltration of monocytes and macrophages into tissues | E28: Monocyte chemoattractant protein-1 (MCP-1), also known as CCL2, is a key inflammatory cytokine that directs immune cells—primarily monocytes and macrophages—to sites of injury and infection. By binding to the specific receptor CCR2, it triggers immune responses and is often measured as a biomarker for systemic inflammation. Mechanism: It induces chemotaxis (directed cell migration) by activating G-protein-coupled receptors.Structure: It is a small 8.6 kDa protein comprised of 76 amino acids, belonging to the CC chemokine family. Cellular Source: It is secreted by a variety of cells, including endothelial, epithelial, smooth muscle, and immune cells, in response to triggers like interleukins or tissue stress
B29: High-sensitivity CRP (hs-CRP) | C29: Less than 1.0 mg/L | D29: Cardiovascular disease (CVD) risk assessment | E29: A high-sensitivity C-reactive protein (hs-CRP) test is a highly precise blood test that measures minute, baseline levels of CRP—a protein produced by the liver in response to inflammation. Unlike standard CRP tests that detect high inflammation (e.g., from infections or severe trauma), hs-CRP identifies subtle, low-grade inflammation. Elevated levels of hs-CRP serve as an independent marker to assess an individual's risk for cardiovascular events like heart attacks and strokes. It is also closely linked to chronic conditions such as obesity, metabolic syndrome, and type 2 diabetes
B30: Fibrosis Markers | E30: Fibrosis markers are clinical tests that measure extracellular matrix (ECM) remodeling, cellular activity, and scarring in tissues. They range from simple blood panels to specialized genetic tests and imaging techniques used for diagnosis, prognosis, and monitoring treatment efficacy. Liver fibrosis staging relies heavily on non-invasive blood scores and specialized algorithms: FIB-4 Index: A mathematical formula using age, AST, ALT, and platelet count. It is commonly used as an initial screening tool. Enhanced Liver Fibrosis (ELF) Test: A proprietary blood panel that measures hyaluronic acid (HA), procollagen III amino-terminal peptide (PIIINP), and tissue inhibitor of metalloproteinase 1 (TIMP-1). FibroTest / FibroMeter: Algorithms integrating direct markers (like α₂-macroglobulin) and indirect markers (such as bilirubin, GGT, and prothrombin time) to assess liver scarring. Direct ECM Markers: Includes type IV collagen, laminin, and YKL-40, which actively track fibrogenesis
B31: Hyaluronic acid (HA) | C31: 0 to 75 ng/mL | D31: Vital for tissue hydration, lubrication, and cellular signaling | E31: Hyaluronic acid (HA) is a natural, clear, gooey polysaccharide produced by the human body. Acting as a powerful humectant, it can hold up to 1,000 times its weight in water. It is primarily concentrated in the skin, eyes, and joints to provide essential lubrication, structural support, and moisture
B32: PIIINP | C32: Adults (general): 1.7 – 4.2 μ g/L or 2.3 – 6.4 μ g/L | D32: A critical serum biomarker used to assess ongoing fibrosis (tissue scarring) and extracellular matrix remodeling in the body | E32: PIIINP stands for Procollagen Type III Amino Terminal Propeptide. It is a protein fragment released into the bloodstream when the body synthesizes collagen type III, which is a major building block of connective tissues in the skin, lungs, liver, and blood vessels. Because it indicates active connective tissue turnover and scarring, measuring PIIINP levels in the serum provides a reliable, non-invasive biomarker for evaluating several important clinical conditions: Monitoring Liver Fibrosis & Cirrhosis: The most common use for the PIIINP test is to monitor for liver toxicity in patients taking the medication Methotrexate (often prescribed for severe psoriasis). Elevated levels warn that the liver is at risk of developing scar tissue. Assessing Systemic Sclerosis: It is widely used to monitor disease activity and organ tissue remodeling in autoimmune conditions like scleroderma. Indicating Cardiovascular Risk: Elevated PIIINP levels can point toward increased arterial stiffness and preclinical cardiovascular or vascular remodeling. Detecting Inflammatory Conditions: High values can also be observed in patients suffering from inflammatory diseases like pulmonary fibrosis, certain types of arthritis, and following major bone fractures. Understanding your PIIINP levels can help doctors track disease progression and liver health without always needing an invasive liver biopsy.
B33: TIMP-1 | C33: Between 100 ng/mL and 220 ng/mL | D33: A vital biomarker in oncology and fibrotic diseases | E33: TIMP-1 (Tissue Inhibitor of Metalloproteinases 1) is a multifunctional, secreted glycoprotein that regulates extracellular matrix (ECM) remodeling. It functions as a natural inhibitor of Matrix Metalloproteinases (MMPs) a class of enzymes responsible for degrading connective tissues.Key Characteristics and Functions MMP Inhibition: It binds to various MMPs (such as MMP-9) in a 1:1 stoichiometric ratio to block enzyme activity, playing a vital role in processes like wound healing and tissue repair. Cellular Signaling: Beyond inhibiting proteases, TIMP-1 acts as a cytokine and growth factor. By interacting with cell-surface receptors like CD63 and integrins, it can promote cell proliferation and inhibit apoptosis. Clinical Relevance: Its dysregulation is heavily implicated in tumor progression, metastasis, cardiovascular remodeling, and fibrotic conditions. Protein Structure TIMP-1 is approximately 23 kDa in size and belongs to the larger TIMP gene family. Its structure is characterized by two distinct domains: The N-terminal domain contains the inhibitory activity that interacts directly with the catalytic site of MMPs. The C-terminal domain is essential for forming complexes with pro-enzymes (proMMPs) and interacting with specific cell receptors
B34: Type IV collagen | C34: 3.6 to 6.9 ng/mL | D34: Genetic mutations in its genes (COL4A3, COL4A4, COL4A5) cause inherited kidney diseases like Alport syndrome, while elevated serum levels serve as prognostic biomarkers for aggressive cancers (like pancreatic cancer) and liver fibrosis | E34: Type IV collagen is a specialized, network-forming collagen that acts as the principal structural component of the basement membrane (the supportive layer underlying all epithelial and endothelial cells). Unlike fibrillar collagens, it forms a flexible, [sheet-like lattice](0.5.1, 0.5.2) critical for tissue organization, filtration, and cell signaling. Key Characteristics Unique Structure: It is a heterotrimer typically consisting of two α1-like and one α2-like chains. Unlike other collagens, its central triple-helical domain contains multiple amino acid interruptions, which grant the molecule structural [flexibility and kinks](0.5.1, 0.5.2, 0.5.3). Network Assembly: The C-terminal (NC1) and N-terminal (7S) domains of the molecules do not get cleaved during processing, allowing them to bind head-to-head and laterally to form a dense, woven meshwork. Genetics: There are six distinct α-chains (α1 to α6) that assemble into various tissue-specific networks
B35: YKL-40 | C35: 20 to 150 μ g/L (or ng/mL) | D35: Strong correlation with inflammation, tissue remodeling, and fibrosis | E35: YKL-40, also known as Chitinase-3-like protein 1 (CHI3L1), is a 40-kDa secreted glycoprotein. Encoded by the CHI3L1 gene, it is produced by various cell types, including macrophages, neutrophils, and vascular smooth muscle cells. While its exact biological function is unclear, it acts as a key biomarker for inflammation, tissue remodeling, and extracellular matrix degradation.Because YKL-40 plays a prominent role in both acute and chronic inflammatory pathways, it is studied across a wide range of pathological conditions.
B36: Osteopontin | C36: Between 28.6 ng/mL and 118.8 ng/mL | D36: Elevated OPN levels serve as a biomarker for cancer progression, metastasis, and chronic inflammation | E36: Osteopontin (OPN) is a multifunctional glycoprotein and key extracellular matrix component that plays a critical role in cell adhesion, migration, and immune regulation. Widely distributed throughout the body, it is heavily involved in bone metabolism, wound healing, and inflammatory responses. Key Characteristics and Functions Structure: OPN is a highly acidic phosphoprotein. It is encoded by the SPP1 gene and contains specific domains (such as RGD) that allow it to interact with cell-surface receptors, primarily integrins and CD44. Physiological Roles: It is essential for normal bone remodeling, where it helps anchor bone-resorbing cells (osteoclasts) to the mineral matrix. It also acts as a cytokine to aid in the recruitment of immune cells to sites of injury. Pathology: Because it promotes cell survival and invasion, OPN is heavily implicated in tumor progression and the tumor microenvironment, often serving as a biomarker in cancer research. It is also highly expressed in chronic inflammatory and autoimmune diseases like [rheumatoid arthritis](0.5.6, 0.5.7). Modifications: Its bioactivity is tightly regulated by post-translational modifications, including phosphorylation and glycosylation, as well as cleavage by enzymes like thrombin.
B37: Apoptosis Markers | E37: Apoptosis (programmed cell death) is identified through biochemical and morphological changes across three main phases: signal, effector, and degradation. Key markers include Annexin V (detects phosphatidylserine on the cell surface), activated Caspases, cleaved PARP, and Cytochrome c release.
B38: Cytokeratin-18 (CK18-M30) | C38: Less than 150 U/L | D38: Hepatocyte apoptosis. | E38: Cytokeratin-18 (specifically the M30 fragment) is a prominent biomarker for epithelial apoptosis (programmed cell death). When liver or epithelial cells undergo apoptosis, they cleave the CK-18 protein, releasing the M30 fragment into the bloodstream. It is widely used in hepatology to assess liver injury and disease severity. CK18-M30 is heavily studied as a non-invasive alternative to liver biopsy for detecting and monitoring non-alcoholic steatohepatitis (NASH). Increased hepatocyte apoptosis leads to highly elevated blood levels, allowing clinicians to track liver inflammation and fibrosis.
B39: Cytokeratin-18 (CK18-M65) | C39: < 300 U/L | D39: A non-invasive blood test to assess the severity of liver diseases, such as non-alcoholic steatohepatitis (NASH), alcoholic liver disease, and various epithelial cancers | E39: Cytokeratin-18 (CK18-M65) is a serum biomarker that measures total cell death, encompassing both apoptosis (programmed cell death) and necrosis (uncontrolled cell death). When epithelial cells, particularly in the liver, are damaged, they release full-length CK18 and its cleaved fragments into the bloodstream, making M65 a key diagnostic tool for monitoring liver injury and disease progression.
B40: Oxidative Stress Markers | E40: Oxidative stress markers are measurable molecules that indicate the extent of cell and tissue damage caused by an imbalance between free radicals and antioxidants. They evaluate DNA/RNA damage (e.g., 8-OHdG), lipid peroxidation (e.g., MDA, F₂-isoprostanes), and protein oxidation (e.g., protein carbonyls) using blood or urine tests
B41: Malondialdehyde (MDA) | C41: 1.0 to 3.0 nmol/mL | D41: Systemic oxidative stress | E41: Malondialdehyde (MDA) is a highly reactive, naturally occurring organic compound with the chemical formula CH₂(CHO)₂. It is predominantly generated in the body as an end-product of lipid peroxidation the oxidative degradation of polyunsaturated fatty acids in cell membranes. Because its levels rise proportionally with free radical damage, MDA serves as a widely utilized, reliable biomarker for oxidative stress. Beyond being a passive indicator, MDA's small structure allows it to freely react with primary amines found in proteins, nucleic acids, and lipids. This reactivity leads to the formation of cross-linked "adducts" that can cause protein denaturation and mutagenic DNA damage. Because of these characteristics, elevated MDA levels in biological fluids (such as blood plasma, serum, and urine) are frequently investigated in studies related to inflammation, aging, and various chronic pathologies.
B42: Superoxide dismutase (SOD) | C42: Between 150 and 240 U/mL | D42: Disease pathology, biomarker utility, and targeted pharmacology | E42: Superoxide dismutase (SOD) is a vital antioxidant enzyme that acts as the body's first line of defense against cell damage. It neutralizes toxic superoxide radicals by converting them into oxygen and less harmful hydrogen peroxide. SOD is a metalloprotein that requires metal ions (such as copper, zinc, or manganese) to function. In humans, it exists in three distinct forms tailored to protect different parts of the cell: SOD1 (Copper-Zinc SOD): Found in the cytoplasm of cells. SOD2 (Manganese SOD): Located in the mitochondria. SOD3 (Extracellular SOD): Found in the spaces between cells, protecting tissues and blood vessels.
B43: Glutathione (GSH) | C43: 46.9 - 90.1 mg/dL | D43: Diagnostic value as a marker for oxidative stress | E43: Glutathione (GSH) is a potent endogenous tripeptide composed of three amino acids: glutamate, cysteine, and glycine. Produced naturally in the liver and cells, it serves as the body’s master antioxidant, preventing cellular damage caused by reactive oxygen species (ROS), free radicals, peroxides, and heavy metals. Glutathione is critical for many physiological processes, including:Protection from Oxidative Stress: By donating a hydrogen from its sulfur (thiol) group, GSH neutralizes free radicals. In the process, it converts into an oxidized form known as GSSG. Detoxification: GSH binds to heavy metals and lipophilic waste products, facilitating their excretion via bile or urine. Cellular Functions: It assists in regulating redox homeostasis, DNA synthesis, and enzyme activation, ensuring proper immune function.
B44: Catalase | C44: 2869 ± 1039 u/g of hemoglobin | D44: Bacterial identification and human pathophysiology | E44: Catalase is an essential antioxidant enzyme found in nearly all aerobic organisms. Its primary function is to catalyze the rapid breakdown of toxic hydrogen peroxide (H₂O₂) into harmless water and oxygen: 2H₂O₂ → 2H₂O + O₂ Biological Importance Cellular Defense: By neutralizing hydrogen peroxide, catalase protects cellular components including DNA, proteins, and cell membranes from severe oxidative damage. Clinical & Microbiological Use: The Microbe Notes Catalase Test is a fundamental biochemical assay used in microbiology to differentiate bacteria (e.g., distinguishing catalase-positive Staphylococcus from catalase-negative Streptococcus). Aging: Reduced catalase activity has been linked to the graying of human hair
...

Sheet Sheet1
A1: Type | B1: Biomarker_ID | D1: Normal Range | E1: Clinical Significance | F1: Description
A2: Blood & Serum Biomarkers | B2: 1. Liver Injury Biomarkers | C2: =VLOOKUP(B2,Class!B:B,2,FALSE) -> #N/A | F2: Liver injury biomarkers are blood tests measuring enzymes and proteins that leak into the bloodstream when liver cells are damaged or when the liver's function is impaired. They are essential for diagnosing, localizing, and monitoring conditions such as hepatitis, cirrhosis, and drug-induced liver injury (DILI).
B3: Routine Liver Function Tests | C3: =VLOOKUP(B3,Class!B:B,2,FALSE) -> #N/A | F3: Routine Liver Function Tests (LFTs) are a group of blood tests used to measure specific enzymes, proteins, and substances to assess overall liver health, screen for infections like hepatitis, monitor medication side effects, and diagnose or monitor liver diseases. The primary components typically measured in a standard LFT profile include: Alanine Aminotransferase (ALT) and Aspartate Aminotransferase (AST): Enzymes concentrated in liver cells. Elevated levels in the bloodstream indicate liver cell injury or inflammation. Alkaline Phosphatase (ALP): An enzyme found in the liver and bones. High levels can suggest issues with the bile ducts or liver damage. Bilirubin: A waste product produced when red blood cells break down, which the liver is responsible for clearing. Elevated levels can cause jaundice and indicate liver disease or blocked bile ducts. Albumin and Total Protein: Albumin is a vital protein created exclusively by the liver, and total protein measures all the proteins in the blood. Low levels can indicate that the liver is not producing proteins properly or may point to chronic kidney/liver conditions. Gamma-glutamyl Transferase (GGT): An enzyme often added to screen for liver and bile duct stress or damage, particularly from alcohol use. Prothrombin Time (PT): Measures how long your blood takes to clot. Because the liver produces clotting factors, an abnormal PT time can indicate impaired liver function.
B4: Alanine aminotransferase (ALT) | C4: =VLOOKUP(B4,Class!B:B,2,FALSE) -> #REF!
B5: Aspartate aminotransferase (AST) | C5: =VLOOKUP(B5,Class!B:B,2,FALSE) -> #REF!
B6: Gamma-glutamyl transferase (GGT) | C6: =VLOOKUP(B6,Class!B:B,2,FALSE) -> #REF!
B7: Alkaline phosphatase (ALP) | C7: =VLOOKUP(B7,Class!B:B,2,FALSE) -> #REF!
B8: Lactate dehydrogenase (LDH) | C8: =VLOOKUP(B8,Class!B:B,2,FALSE) -> #N/A
B9: Total bilirubin | C9: =VLOOKUP(B9,Class!B:B,2,FALSE) -> #N/A
B10: Direct bilirubin | C10: =VLOOKUP(B10,Class!B:B,2,FALSE) -> #N/A
B11: Indirect bilirubin | C11: =VLOOKUP(B11,Class!B:B,2,FALSE) -> #N/A
B12: Liver Synthetic Function | C12: =VLOOKUP(B12,Class!B:B,2,FALSE) -> #N/A | F12: Liver synthetic function is the organ's ability to produce essential blood proteins, coagulation factors, and biochemical molecules. It is clinically assessed by measuring serum albumin (for chronic capacity) and prothrombin time/INR (for acute capacity). Core Synthetic ProcessesProtein Synthesis: The liver produces roughly 90% of circulating blood proteins, most notably albumin. Albumin maintains intravascular oncotic pressure and transports hormones, fatty acids, and drugs. It also synthesizes carrier proteins like transferrin (for iron transport). Coagulation Factors: The liver is the primary site of synthesis for nearly all clotting factors (e.g., fibrinogen, prothrombin, factors V, VII, IX, and X). It also synthesizes natural anticoagulants like protein C and protein S. Metabolite and Energy Production: The liver continuously synthesizes lipids, cholesterol (to build cell membranes and bile acids), and lipoproteins. During fasting, it synthesizes glucose (gluconeogenesis) and produces ketone bodies as alternative brain fuel. Regulatory Molecules: It creates key hormones and regulatory proteins, such as thrombopoietin (which stimulates platelet production) and angiotensinogen (which regulates blood pressure). Clinical Significance & Testing Because the liver has a large functional reserve, synthetic function typically remains well-preserved until liver disease becomes advanced or chronic (e.g., cirrhosis). Albumin Testing: Albumin has a long circulatory half-life (about 21 days). A low serum level (hypoalbuminemia) indicates long-term, chronic liver impairment or severe malnutrition. PT/INR Testing: The liver's coagulation factors have much shorter half-lives. Prolonged prothrombin time (PT) or an elevated international normalized ratio (INR) serves as a highly sensitive, acute indicator of failing synthetic capacity and elevated bleeding risk.
B13: Albumin | C13: =VLOOKUP(B13,Class!B:B,2,FALSE) -> #N/A
B14: Total protein | C14: =VLOOKUP(B14,Class!B:B,2,FALSE) -> #N/A
B15: Globulin | C15: =VLOOKUP(B15,Class!B:B,2,FALSE) -> #N/A
B16: Albumin/Globulin ratio | C16: =VLOOKUP(B16,Class!B:B,2,FALSE) -> #N/A
B17: Prothrombin time (PT) | C17: =VLOOKUP(B17,Class!B:B,2,FALSE) -> #N/A
B18: International Normalized Ratio (INR) | C18: =VLOOKUP(B18,Class!B:B,2,FALSE) -> #N/A
B19: 2. Metabolic Biomarkers | C19: =VLOOKUP(B19,Class!B:B,2,FALSE) -> #N/A | F19: Metabolic biomarkers are measurable biological indicators such as specific molecules or hormones in blood or urine that reflect how your body processes and utilizes energy. They are crucial for diagnosing metabolic conditions (like diabetes and cardiovascular disease), tracking organ function, and evaluating your overall physiological health. The most critical metabolic biomarkers are often grouped into a standard metabolic panel: Blood Glucose & Insulin: Measures your body's ability to process sugars. Indicators like fasting glucose and HbA1c (average blood sugar over 3 months) identify risks for insulin resistance and type 2 diabetes. Lipid Profile: Tracks fat-based particles in your blood. Key markers include triglycerides, HDL (high-density lipoprotein/"good" cholesterol), and LDL (low-density lipoprotein/"bad" cholesterol) to assess cardiovascular risk. Liver & Kidney Markers: Biomarkers like ALT (alanine aminotransferase) for liver health and BUN/Creatinine for kidney function help catch organ stress or damage early. Inflammatory Markers: Proteins like hs-CRP (high-sensitivity C-reactive protein) indicate chronic, low-grade inflammation, which is often tied to metabolic syndrome
B20: Glucose Metabolism | C20: =VLOOKUP(B20,Class!B:B,2,FALSE) -> #N/A | F20: Glucose metabolism refers to the bodily processes that break down, utilize, and store glucose (sugar) from food. It is the primary way your cells generate energy to keep your body functioning. How the Process Works? Glucose metabolism encompasses a few key, continuous processes to manage energy:Glycolysis: The breakdown of glucose in cells to produce immediate energy in the form of ATP (Adenosine Triphosphate).Glycogenesis: The synthesis and storage of excess glucose as glycogen (primarily in the liver and muscles) for later use.Glycogenolysis: The breakdown of stored glycogen back into glucose when blood sugar is low (like during sleep or fasting).Gluconeogenesis: The synthesis of new glucose from non-carbohydrate sources, such as amino acids, when energy reserves are depleted. The Role of Hormones This intricate process is heavily regulated by hormones released by the pancreas:Insulin: Secreted after a meal to lower blood sugar. It acts as a key, unlocking cell membranes so glucose can enter tissue cells for energy or storage.Glucagon: Secreted during fasting to raise blood sugar. It signals the liver to convert stored glycogen back into glucose. Why It Matters? Glucose is the essential fuel source for nearly all cells, especially the brain and nervous system. When glucose metabolism functions normally, your body maintains a healthy, balanced blood sugar level.Impairments or breakdowns in this system such as insulin resistance, where cells fail to respond effectively to insulin often lead to conditions like prediabetes or type 2 diabetes.
B21: Fasting blood glucose (FBG) | C21: =VLOOKUP(B21,Class!B:B,2,FALSE) -> #N/A
B22: Random blood glucose | C22: =VLOOKUP(B22,Class!B:B,2,FALSE) -> #N/A
B23: Hemoglobin A1c (HbA1c) | C23: =VLOOKUP(B23,Class!B:B,2,FALSE) -> #N/A
B24: Fasting insulin | C24: =VLOOKUP(B24,Class!B:B,2,FALSE) -> #N/A
B25: C-peptide | C25: =VLOOKUP(B25,Class!B:B,2,FALSE) -> #N/A
B26: HOMA-IR | C26: =VLOOKUP(B26,Class!B:B,2,FALSE) -> #REF!
B27: HOMA-β | C27: =VLOOKUP(B27,Class!B:B,2,FALSE) -> #N/A
B28: Lipid Profile | C28: =VLOOKUP(B28,Class!B:B,2,FALSE) -> #N/A | F28: A lipid profile (or lipid panel) is a blood test that measures the amount of cholesterol and other fats in your blood. It is a crucial screening tool used by doctors to assess your cardiovascular health and determine your risk for developing heart disease, blockages in your arteries, or having a stroke. A standard lipid profile typically measures the following specific components: Total Cholesterol: The overall amount of cholesterol circulating in your bloodstream (including both "good" and "bad" types). Optimal Level: Below 200 mg/dL.Low-Density Lipoprotein (LDL) Cholesterol: Often referred to as "bad cholesterol". High levels can build up in the walls of your blood vessels, forming plaque that restricts blood flow and increases the risk of heart attacks. Optimal Level: Below 100 mg/dL. High-Density Lipoprotein (HDL) Cholesterol: Known as "good cholesterol". It actively sweeps excess cholesterol out of your bloodstream and transports it back to the liver to be broken down, offering protection against heart disease. Optimal Level: 60 mg/dL or higher. Triglycerides: A type of fat (lipid) that your body makes from excess calories and the food you eat. They are stored in your fat cells for energy, but high levels are linked to a higher risk of heart disease and insulin resistance. Optimal Level: Below 150 mg/dL. Very Low-Density Lipoprotein (VLDL) Cholesterol: Often calculated based on your triglyceride level. VLDL mainly carries triglycerides in the blood and high levels can also indicate a risk of artery blockages. Optimal Level: Below 30 mg/dL
B29: Total cholesterol | C29: =VLOOKUP(B29,Class!B:B,2,FALSE) -> #REF!
B30: Triglycerides | C30: =VLOOKUP(B30,Class!B:B,2,FALSE) -> #REF!
B31: HDL cholesterol | C31: =VLOOKUP(B31,Class!B:B,2,FALSE) -> #N/A
B32: LDL cholesterol | C32: =VLOOKUP(B32,Class!B:B,2,FALSE) -> #N/A
B33: VLDL cholesterol | C33: =VLOOKUP(B33,Class!B:B,2,FALSE) -> #N/A
B34: Non-HDL cholesterol | C34: =VLOOKUP(B34,Class!B:B,2,FALSE) -> #N/A
B35: Free fatty acids (FFA) | C35: =VLOOKUP(B35,Class!B:B,2,FALSE) -> #N/A
B36: Apolipoprotein A1 | C36: =VLOOKUP(B36,Class!B:B,2,FALSE) -> #N/A
B37: Apolipoprotein B | C37: =VLOOKUP(B37,Class!B:B,2,FALSE) -> #N/A
B38: Lipoprotein(a) | C38: =VLOOKUP(B38,Class!B:B,2,FALSE) -> #N/A
B39: 3. Inflammatory Biomarkers | C39: =VLOOKUP(B39,Class!B:B,2,FALSE) -> #N/A | F39: Inflammatory biomarkers are measurable substances in the body such as proteins, enzymes, and cells that indicate the presence and severity of inflammation. Doctors use blood or stool tests to detect these markers, which helps diagnose infections, autoimmune diseases, and chronic conditions like heart disease or inflammatory bowel disease. Because inflammatory biomarkers are typically non-specific meaning an elevated level signals inflammation but rarely points to a single, exact cause they are usually ordered alongside a thorough physical exam and clinical history. The most common inflammatory biomarkers include: C-Reactive Protein (CRP): Produced by the liver, CRP is the most widely used marker to detect acute inflammation caused by severe infections, tissue damage, or autoimmune flare-ups. A specialized version, hs-CRP (High-Sensitivity CRP), is used to measure low-grade chronic inflammation and assess cardiovascular risk. Erythrocyte Sedimentation Rate (ESR): This test measures how quickly red blood cells settle in a test tube. Inflammatory proteins cause red blood cells to clump and settle faster, signaling ongoing inflammation. Cytokines: These are small signaling proteins (such as Interleukin-6 and TNF-alpha) that regulate immune responses. They are often elevated in severe inflammatory conditions and cancers. Procalcitonin (PCT): This marker is particularly useful for detecting severe bacterial infections and guiding antibiotic therapy, especially in cases of sepsis. Plasma Viscosity (PV): Similar to ESR, this measures the thickness of blood plasma. It is sometimes preferred over ESR because it is not affected by a patient's age or sex. Calprotectin: Frequently measured in stool samples, this protein is a highly reliable biomarker for intestinal inflammation, aiding in the diagnosis and monitoring of Inflammatory Bowel Disease (IBD)
B40: Cytokines | C40: =VLOOKUP(B40,Class!B:B,2,FALSE) -> #N/A | F40: Cytokines are small proteins secreted by cells that act as chemical messengers. They are essential for regulating the immune system, controlling inflammation, and dictating how cells grow and divide. When the body faces an infection or injury, immune and non-immune cells release cytokines to coordinate a targeted defense. Key Types of Cytokines Cytokines are categorized into several major groups based on their structure and function: Interleukins (ILs): Regulate immune and inflammatory responses, often acting as messengers between different white blood cells. Chemokines: Direct immune cells to the specific site of an infection or tissue damage through a process called chemotaxis. Interferons (IFNs): Help defend against viruses by preventing them from multiplying and stimulating other immune cells to fight the infection. Tumor Necrosis Factors (TNFs): Help trigger inflammation and can directly destroy certain types of cells, including cancer cells. Colony-Stimulating Factors (CSFs): Stimulate the bone marrow to produce and differentiate new blood and immune cells. How They Work? Cytokines operate by binding to specific receptors on the surface of target cells. This binding triggers a chain reaction inside the cell that tells it to grow, die, or move. They act in three primary ways: Autocrine: A cell secretes cytokines to signal itself. Paracrine: A cell secretes cytokines to signal nearby, neighboring cells. Endocrine: Cytokines enter the bloodstream to signal distant cells or organs (e.g., triggering a fever in the brain). Medical Relevance! Because they dictate how the body responds to illness, cytokines are heavily studied in medicine. An overreaction of the immune system can cause a dangerous flood of cytokines, known as a cytokine storm, which can damage healthy tissues. Conversely, lab-made versions of cytokines (like Interleukin-2) are used as immunotherapies to treat certain conditions, such as advanced kidney cancer and metastatic melanoma.
...

Sheet Blood and Serum
A1: Type | B1: Biomarker_ID | C1: Description
A2: Blood & Serum Biomarkers | B2: 1. Liver Injury Biomarkers | C2: Liver injury biomarkers are blood tests measuring enzymes and proteins that leak into the bloodstream when liver cells are damaged or when the liver's function is impaired. They are essential for diagnosing, localizing, and monitoring conditions such as hepatitis, cirrhosis, and drug-induced liver injury (DILI).
B3: Routine Liver Function Tests | C3: Routine Liver Function Tests (LFTs) are a group of blood tests used to measure specific enzymes, proteins, and substances to assess overall liver health, screen for infections like hepatitis, monitor medication side effects, and diagnose or monitor liver diseases. The primary components typically measured in a standard LFT profile include: Alanine Aminotransferase (ALT) and Aspartate Aminotransferase (AST): Enzymes concentrated in liver cells. Elevated levels in the bloodstream indicate liver cell injury or inflammation. Alkaline Phosphatase (ALP): An enzyme found in the liver and bones. High levels can suggest issues with the bile ducts or liver damage. Bilirubin: A waste product produced when red blood cells break down, which the liver is responsible for clearing. Elevated levels can cause jaundice and indicate liver disease or blocked bile ducts. Albumin and Total Protein: Albumin is a vital protein created exclusively by the liver, and total protein measures all the proteins in the blood. Low levels can indicate that the liver is not producing proteins properly or may point to chronic kidney/liver conditions. Gamma-glutamyl Transferase (GGT): An enzyme often added to screen for liver and bile duct stress or damage, particularly from alcohol use. Prothrombin Time (PT): Measures how long your blood takes to clot. Because the liver produces clotting factors, an abnormal PT time can indicate impaired liver function.
B4: Alanine aminotransferase (ALT)
B5: Aspartate aminotransferase (AST)
B6: Gamma-glutamyl transferase (GGT)
B7: Alkaline phosphatase (ALP)
B8: Lactate dehydrogenase (LDH)
B9: Total bilirubin
B10: Direct bilirubin
B11: Indirect bilirubin
B12: Liver Synthetic Function | C12: Liver synthetic function is the organ's ability to produce essential blood proteins, coagulation factors, and biochemical molecules. It is clinically assessed by measuring serum albumin (for chronic capacity) and prothrombin time/INR (for acute capacity). Core Synthetic ProcessesProtein Synthesis: The liver produces roughly 90% of circulating blood proteins, most notably albumin. Albumin maintains intravascular oncotic pressure and transports hormones, fatty acids, and drugs. It also synthesizes carrier proteins like transferrin (for iron transport). Coagulation Factors: The liver is the primary site of synthesis for nearly all clotting factors (e.g., fibrinogen, prothrombin, factors V, VII, IX, and X). It also synthesizes natural anticoagulants like protein C and protein S. Metabolite and Energy Production: The liver continuously synthesizes lipids, cholesterol (to build cell membranes and bile acids), and lipoproteins. During fasting, it synthesizes glucose (gluconeogenesis) and produces ketone bodies as alternative brain fuel. Regulatory Molecules: It creates key hormones and regulatory proteins, such as thrombopoietin (which stimulates platelet production) and angiotensinogen (which regulates blood pressure). Clinical Significance & Testing Because the liver has a large functional reserve, synthetic function typically remains well-preserved until liver disease becomes advanced or chronic (e.g., cirrhosis). Albumin Testing: Albumin has a long circulatory half-life (about 21 days). A low serum level (hypoalbuminemia) indicates long-term, chronic liver impairment or severe malnutrition. PT/INR Testing: The liver's coagulation factors have much shorter half-lives. Prolonged prothrombin time (PT) or an elevated international normalized ratio (INR) serves as a highly sensitive, acute indicator of failing synthetic capacity and elevated bleeding risk.
B13: Albumin
B14: Total protein
B15: Globulin
B16: Albumin/Globulin ratio
B17: Prothrombin time (PT)
B18: International Normalized Ratio (INR)
B19: 2. Metabolic Biomarkers | C19: Metabolic biomarkers are measurable biological indicators such as specific molecules or hormones in blood or urine that reflect how your body processes and utilizes energy. They are crucial for diagnosing metabolic conditions (like diabetes and cardiovascular disease), tracking organ function, and evaluating your overall physiological health. The most critical metabolic biomarkers are often grouped into a standard metabolic panel: Blood Glucose & Insulin: Measures your body's ability to process sugars. Indicators like fasting glucose and HbA1c (average blood sugar over 3 months) identify risks for insulin resistance and type 2 diabetes. Lipid Profile: Tracks fat-based particles in your blood. Key markers include triglycerides, HDL (high-density lipoprotein/"good" cholesterol), and LDL (low-density lipoprotein/"bad" cholesterol) to assess cardiovascular risk. Liver & Kidney Markers: Biomarkers like ALT (alanine aminotransferase) for liver health and BUN/Creatinine for kidney function help catch organ stress or damage early. Inflammatory Markers: Proteins like hs-CRP (high-sensitivity C-reactive protein) indicate chronic, low-grade inflammation, which is often tied to metabolic syndrome
B20: Glucose Metabolism | C20: Glucose metabolism refers to the bodily processes that break down, utilize, and store glucose (sugar) from food. It is the primary way your cells generate energy to keep your body functioning. How the Process Works? Glucose metabolism encompasses a few key, continuous processes to manage energy:Glycolysis: The breakdown of glucose in cells to produce immediate energy in the form of ATP (Adenosine Triphosphate).Glycogenesis: The synthesis and storage of excess glucose as glycogen (primarily in the liver and muscles) for later use.Glycogenolysis: The breakdown of stored glycogen back into glucose when blood sugar is low (like during sleep or fasting).Gluconeogenesis: The synthesis of new glucose from non-carbohydrate sources, such as amino acids, when energy reserves are depleted. The Role of Hormones This intricate process is heavily regulated by hormones released by the pancreas:Insulin: Secreted after a meal to lower blood sugar. It acts as a key, unlocking cell membranes so glucose can enter tissue cells for energy or storage.Glucagon: Secreted during fasting to raise blood sugar. It signals the liver to convert stored glycogen back into glucose. Why It Matters? Glucose is the essential fuel source for nearly all cells, especially the brain and nervous system. When glucose metabolism functions normally, your body maintains a healthy, balanced blood sugar level.Impairments or breakdowns in this system such as insulin resistance, where cells fail to respond effectively to insulin often lead to conditions like prediabetes or type 2 diabetes.
B21: Fasting blood glucose (FBG)
B22: Random blood glucose
B23: Hemoglobin A1c (HbA1c)
B24: Fasting insulin
B25: C-peptide
B26: HOMA-IR
B27: HOMA-β
B28: Lipid Profile | C28: A lipid profile (or lipid panel) is a blood test that measures the amount of cholesterol and other fats in your blood. It is a crucial screening tool used by doctors to assess your cardiovascular health and determine your risk for developing heart disease, blockages in your arteries, or having a stroke. A standard lipid profile typically measures the following specific components: Total Cholesterol: The overall amount of cholesterol circulating in your bloodstream (including both "good" and "bad" types). Optimal Level: Below 200 mg/dL.Low-Density Lipoprotein (LDL) Cholesterol: Often referred to as "bad cholesterol". High levels can build up in the walls of your blood vessels, forming plaque that restricts blood flow and increases the risk of heart attacks. Optimal Level: Below 100 mg/dL. High-Density Lipoprotein (HDL) Cholesterol: Known as "good cholesterol". It actively sweeps excess cholesterol out of your bloodstream and transports it back to the liver to be broken down, offering protection against heart disease. Optimal Level: 60 mg/dL or higher. Triglycerides: A type of fat (lipid) that your body makes from excess calories and the food you eat. They are stored in your fat cells for energy, but high levels are linked to a higher risk of heart disease and insulin resistance. Optimal Level: Below 150 mg/dL. Very Low-Density Lipoprotein (VLDL) Cholesterol: Often calculated based on your triglyceride level. VLDL mainly carries triglycerides in the blood and high levels can also indicate a risk of artery blockages. Optimal Level: Below 30 mg/dL
B29: Total cholesterol
B30: Triglycerides
B31: HDL cholesterol
B32: LDL cholesterol
B33: VLDL cholesterol
B34: Non-HDL cholesterol
B35: Free fatty acids (FFA)
B36: Apolipoprotein A1
B37: Apolipoprotein B
B38: Lipoprotein(a)
